<?xml version="1.0" encoding="utf-8"?>
<!-- https://myminifactory.github.io/Fast-Quadric-Mesh-Simplification/ -->
<robot name="mecabot">

  <link name="base_footprint"/>

  <joint name="base_footprint_to_base_link" type="fixed">
    <parent link="base_footprint"/>
    <child link="base_link"/>
    <origin xyz="0 0 0.017" rpy="0 0 0"/>
  </joint> 

  <link name="base_link">
    <inertial>
      <origin xyz="-0.0018184 0.0044834 0.11192" rpy="0 0 0" />
      <!-- <origin xyz="0 0 0" rpy="0 0 0" /> -->
      <mass value="13.462" />
      <!-- <mass value="0.00001" /> -->
      <inertia
        ixx="0.094165"
        ixy="0.00032939"
        ixz="9.5703E-07"
        iyy="0.18301"
        iyz="-1.1521E-05"
        izz="0.26421" />
    </inertial>
    <visual>
      <origin
        xyz="0 0 0"
        rpy="0 0 0" />
      <geometry>
        <!-- <box size="0.8 0.4 0.1" /> -->
        <!-- <mesh
          filename="package://mecabot_description/meshes/base_link.STL" /> -->
        
        <mesh
          filename="package://mecabot_description/meshes/simplify_base_link.stl" />

          
      </geometry>
      <material
        name="">
        <color
          rgba="0.79216 0.81961 0.93333 1" />
      </material>
    </visual>
    <collision>
      <origin
        xyz="0 0 0"
        rpy="0 0 0" />
      <geometry>
        <!-- <box size="0.8 0.4 0.1" /> -->
        <mesh
          filename="package://mecabot_description/meshes/simplify_base_link.stl" />
        <!-- <mesh
          filename="package://mecabot_description/meshes/base_link.STL" /> -->
      </geometry>
    </collision>
  </link>
  <link name="left_front_wheel">
    <inertial>
      <origin
        xyz="-4.7947E-07 1.9745E-07 0.041008"
        rpy="0 0 0" />
      <!-- <mass
        value="1.7325" /> -->
      <mass
        value="0.2" />
      <inertia
        ixx="0.0039425"
        ixy="6.0925E-09"
        ixz="6.139E-08"
        iyy="0.0039425"
        iyz="-2.4887E-08"
        izz="0.0062624" />
    </inertial>
    <visual>
      <origin
        xyz="0 0 0"
        rpy="0 0 0" />
      <geometry>
        <mesh
          filename="package://mecabot_description/meshes/left_front_wheel.STL" />
      </geometry>
      <material
        name="">
        <color
          rgba="0.77647 0.75686 0.73725 1" />
      </material>
    </visual>
    <collision>
      <origin
        xyz="0 0 0.04"
        rpy="0 0 0" />
      <geometry>
      
        <cylinder length="0.07" radius="0.09"/>
        <!-- <mesh
          filename="package://mecabot_description/meshes/left_front_wheel.STL" /> -->
      </geometry>
      <!-- <surface>
        
          <friction>
            <ode>
              <mu>10000000.0</mu>
              <mu2>10000000.0</mu2>
              <fdir1>1 0 0</fdir1>
              <slip1>0.0</slip1>
              <slip2>0.0</slip2>
            </ode>
        </friction>
      </surface> -->
    </collision>
  </link>
  <joint
    name="base_link_to_left_front_wheel"
    type="continuous">
    <origin
      xyz="0.23 0.25046 0.0735"
      rpy="1.5708 0 0" />
    <!-- <origin
      xyz="0.23 0.25046 0.0"
      rpy="1.5708 0 0" /> -->
    <parent
      link="base_link" />
    <child
      link="left_front_wheel" />
    <axis
      xyz="0 0 1" />
    <limit
      effort="10.0"
      velocity="100.0" />
  </joint>
  <link
    name="right_front_wheel">
    <inertial>
      <origin
        xyz="6.0145483038454E-10 5.18529396989487E-07 -0.0365083775680031"
        rpy="0 0 0" />
      <!-- <mass
        value="1.7325" /> -->
      <mass
        value="0.2" />
      <inertia
        ixx="0.00394252591369729"
        ixy="-1.10239278458684E-08"
        ixz="4.4040694426611E-10"
        iyy="0.00394252262736816"
        iyz="6.62412528978017E-08"
        izz="0.0062623693571568" />
    </inertial>
    <visual>
      <origin
        xyz="0 0 0"
        rpy="0 0 0" />
      <geometry>
        <mesh
          filename="package://mecabot_description/meshes/right_front_wheel.STL" />
      </geometry>
      <material
        name="">
        <color
          rgba="0.776470588235294 0.756862745098039 0.737254901960784 1" />
      </material>
    </visual>
    <collision>
      <origin
        xyz="0 0 -0.04"
        rpy="0 0 0" />
      <geometry>
        <cylinder length="0.07" radius="0.09"/>
        <!-- <mesh
          filename="package://mecabot_description/meshes/right_front_wheel.STL" /> -->
      </geometry>
      <!-- <surface>
        
          <friction>
            <ode>
              <mu>10000000.0</mu>
              <mu2>10000000.0</mu2>
              <fdir1>1 0 0</fdir1>
              <slip1>0.0</slip1>
              <slip2>0.0</slip2>
            </ode>
        </friction>
      </surface> -->
    </collision>
  </link>
  <joint
    name="base_link_to_right_front_wheel"
    type="continuous">
    <origin
      xyz="0.23 -0.24604 0.0735"
      rpy="1.5708 0 0" />
    <parent
      link="base_link" />
    <child
      link="right_front_wheel" />
    <axis
      xyz="0 0 1" />
    <limit
      effort="10.0"
      velocity="100.0" />
  </joint>
  <link
    name="left_rear_wheel">
    <inertial>
      <origin
        xyz="-4.7947020670458E-07 1.9744762028151E-07 0.0410083775672223"
        rpy="0 0 0" />
      <!-- <mass
        value="1.7325" /> -->
      <mass
        value="0.2" />
      <inertia
        ixx="0.00394251925675899"
        ixy="6.09246594179119E-09"
        ixz="6.13899443516379E-08"
        iyy="0.00394252578615664"
        iyz="-2.48871320413608E-08"
        izz="0.00626236571649836" />
    </inertial>
    <visual>
      <origin
        xyz="0 0 0"
        rpy="0 0 0" />
      <geometry>
        <mesh
          filename="package://mecabot_description/meshes/left_rear_wheel.STL" />
      </geometry>
      <material
        name="">
        <color
          rgba="0.776470588235294 0.756862745098039 0.737254901960784 1" />
      </material>
    </visual>
    <collision>
      <!-- <origin
        xyz="0 0 0"
        rpy="0 0 0" /> -->
      <origin
        xyz="0 0 0.04"
        rpy="0 0 0" />
      <geometry>
        <cylinder length="0.07" radius="0.09"/>
        <!-- <mesh
          filename="package://mecabot_description/meshes/left_rear_wheel.STL" /> -->
      </geometry>
      <!-- <surface>
        
          <friction>
            <ode>
              <mu>10000000.0</mu>
              <mu2>10000000.0</mu2>
              <fdir1>1 0 0</fdir1>
              <slip1>0.0</slip1>
              <slip2>0.0</slip2>
            </ode>
        </friction>
      </surface> -->
    </collision>
  </link>
  <joint
    name="base_link_to_left_rear_wheel"
    type="continuous">
    <origin
      xyz="-0.23 0.25046 0.0735"
      rpy="1.5708 0 0" />
    <parent
      link="base_link" />
    <child
      link="left_rear_wheel" />
    <axis
      xyz="0 0 1" />
    <limit
      effort="10.0"
      velocity="100.0" />
  </joint>
  <link
    name="right_rear_wheel">
    <inertial>
      <origin
        xyz="6.012884634643E-10 5.18529179580063E-07 -0.0410083775679985"
        rpy="0 0 0" />
      <!-- <mass
        value="1.7325" /> -->
      <mass
        value="0.2" />
      <inertia
        ixx="0.00394252591373319"
        ixy="-1.10239514995405E-08"
        ixz="4.4041442628534E-10"
        iyy="0.00394252262734861"
        iyz="6.62412598386314E-08"
        izz="0.00626236935717058" />
    </inertial>
    <visual>
      <origin
        xyz="0 0 0"
        rpy="0 0 0" />
      <geometry>
        <mesh
          filename="package://mecabot_description/meshes/right_rear_wheel.STL" />
      </geometry>
      <material
        name="">
        <color
          rgba="0.776470588235294 0.756862745098039 0.737254901960784 1" />
      </material>
    </visual>
    <collision>
      <origin
        xyz="0 0 -0.04"
        rpy="0 0 0" />
      <geometry>
        <cylinder length="0.07" radius="0.09"/>
        <!-- <mesh
          filename="package://mecabot_description/meshes/right_rear_wheel.STL" /> -->
      </geometry>
      <!-- <surface>
       
          <friction>
            <ode>
              <mu>10000000.0</mu>
              <mu2>10000000.0</mu2>
              <fdir1>1 0 0</fdir1>
              <slip1>0.0</slip1>
              <slip2>0.0</slip2>
            </ode>
        </friction>
      </surface> -->
    </collision>
  </link>
  <joint
    name="base_link_to_right_rear_wheel"
    type="continuous">
    <!-- fixed -->
    <!-- continuous -->
    <origin
      xyz="-0.23 -0.25054 0.0735"
      rpy="1.5708 0 0" />
    <parent
      link="base_link" />
    <child
      link="right_rear_wheel" />
    <axis
      xyz="0 0 1" />
    <limit
      effort="10.0"
      velocity="100.0" />
  </joint>

  <gazebo>
    <plugin name="object_controller" filename="libgazebo_ros_planar_move.so">
       
      <commandTopic>cmd_vel</commandTopic>
      <odometryTopic>odom/unfiltered</odometryTopic>
      
      <ros>    
        <!-- <remapping>/tf:=tf</remapping> 
        <remapping>/tf_static:=tf_static</remapping>  -->
        <!-- <robotNamespace><remapping>/tf:=tf</remapping>  </robotNamespace> -->
        <remapping>odom:=odom/unfiltered</remapping>   
      </ros>

    
      <odometryRate>20</odometryRate>
    
      <publish_rate>10</publish_rate>

      
      <!-- <publish_odom>true</publish_odom> -->
      <!-- <publish_odom_tf>true</publish_odom_tf> -->

     
      <!-- <odometryFrame>odom</odometryFrame> -->
      <odometry_frame>odom</odometry_frame>

      <!-- <robotBaseFrame>base_link</robotBaseFrame> -->
      <robot_base_frame>base_footprint</robot_base_frame>
      <publish_odom>true</publish_odom>
      <!-- <publish_odom>false</publish_odom> -->
      <publish_odom_tf>false</publish_odom_tf>
      <!-- <publish_odom_tf>true</publish_odom_tf> -->

      
      <!-- <covariance_x>0.0001</covariance_x>
      <covariance_y>0.0001</covariance_y>
      <covariance_yaw>0.01</covariance_yaw> -->

      <leftFrontJoint>base_link_to_left_front_wheel</leftFrontJoint>
      <rightFrontJoint>base_link_to_right_front_wheel</rightFrontJoint>
      <leftRearJoint>base_link_to_left_rear_wheel</leftRearJoint>
      <rightRearJoint>base_link_to_right_rear_wheel</rightRearJoint>

    </plugin>  
  </gazebo>
  <!-- <gazebo>
    <plugin name="gazebo_ros_mecanum_diff_drive" filename="libgazebo_ros_mecanum_diff_drive.so">
      <commandTopic>cmd_vel</commandTopic>
      <odometryTopic>odom</odometryTopic>
      <odometryFrame>odom</odometryFrame>
      <robotBaseFrame>base_footprint</robotBaseFrame>
     
      <LeftRear>base_link_to_left_rear_wheel</LeftRear>
      <LeftFront>base_link_to_left_front_wheel</LeftFront>
      <RightFront>base_link_to_right_front_wheel</RightFront>
      <RightRear>base_link_to_right_rear_wheel</RightRear>
      <odometryRate>20</odometryRate>      
      <publishWheelTF>true</publishWheelTF>
      <publishWheelJointState>true</publishWheelJointState>
      <WheelTorque>1</WheelTorque>
      <WheelSeparationW>0.5</WheelSeparationW>
      <WheelSeparationL>0.6</WheelSeparationL>
      <wheelAccel>5</wheelAccel>
      <wheelDiameter>0.13</wheelDiameter>
      <publishOdom>false</publishOdom>
      <isRollerModel>true</isRollerModel>
    </plugin>
  </gazebo> -->

  <!-- <gazebo>
    <plugin name="rosa_controller" filename="libgazebo_ros_omni_drive.so">
      <commandTopic>cmd_vel</commandTopic>
      <odometryTopic>odom</odometryTopic>
      <odometryFrame>odom</odometryFrame>
      <odometryRate>20.0</odometryRate>
      <robotBaseFrame>base_link</robotBaseFrame>
      <wheel_radius>0.09</wheel_radius>
      <base_length>0.496</base_length>
      <base_width>0.46</base_width>
      <front_left_joint>base_link_to_left_front_wheel</front_left_joint>
      <front_right_joint>base_link_to_right_front_wheel</front_right_joint>
      <rear_left_joint>base_link_to_left_rear_wheel</rear_left_joint>
      <rear_right_joint>base_link_to_right_rear_wheel</rear_right_joint>
      <wheel_max_speed> 20.0 </wheel_max_speed>
      <wheel_acceleration> 20.0</wheel_acceleration>
      <joint_config>-1 -1 -1 -1</joint_config>
    </plugin>
  </gazebo> -->


  <joint name="front_lidar_joint" type="fixed">
    <parent link="base_link"/>
    <child link="front_lidar"/>
    <origin rpy="0 0 0" xyz="0.35 0.2 0.2"/>
    <axis xyz="0 0 1"/>
  </joint> 
  <link name="front_lidar">
    <visual>
      <!-- <origin rpy="0 0 0" xyz="0 0 0.385"/> -->
      <geometry>
        <!-- <cylinder length="0.6" radius="0.2"/> -->
        <cylinder length="0.035" radius="0.035"/>
      </geometry>
      <material name="blue"/>
    </visual>
  </link>

  <joint name="rear_lidar_joint" type="fixed">
    <parent link="base_link"/>
    <child link="rear_lidar"/>
    <origin rpy="0 0 3.1416" xyz="-0.35 -0.2 0.2"/>
    <axis xyz="0 0 1"/>
  </joint> 
  <link name="rear_lidar">
    <visual>
      <!-- <origin rpy="0 0 0" xyz="0 0 0.385"/> -->
      <geometry>
        <!-- <cylinder length="0.6" radius="0.2"/> -->
        <cylinder length="0.035" radius="0.035"/>
      </geometry>
      <material name="blue"/>
    </visual>
  </link>

  <link name="imu_link">
  </link>
  <joint name="imu_joint" type="fixed">
    <parent link="base_link"/>
    <child link="imu_link"/>
    <!-- <origin rpy="0 0 0.0" xyz="0 0 0"/>
    <axis xyz="0 0 1"/> -->
  </joint> 


  <!-- front LiDAR controller -->
  <gazebo reference="front_lidar">
    <sensor type="ray" name="RPLIDAR_s3_front_sensor">
      <pose>0 0 0 0 0 0</pose>
      <always_on>true</always_on>
      <visualize>true</visualize>
      <update_rate>10</update_rate>
      <ray>
        <scan>
          <horizontal>
            <samples>500</samples>
            <resolution>1</resolution>
            <min_angle>-1.57</min_angle>
            <max_angle>3.1416</max_angle>
            <!-- <max_angle>1.57</max_angle> -->
          </horizontal>
        </scan>
        <range>
          <min>0.10</min>
          <max>30.0</max>
          <resolution>0.01</resolution>
        </range>
        <noise>
          <type>gaussian</type>
          <mean>0.0</mean>
          <stddev>0.01</stddev>
        </noise>
      </ray>
      <plugin name="gazebo_ros_lidar_front_controller" filename="libgazebo_ros_ray_sensor.so">
        <ros>
            <!-- <namespace>/tb3</namespace> -->
            <remapping>~/out:=/laser/front</remapping>
          </ros>
        <output_type>sensor_msgs/LaserScan</output_type>
        <frame_name>front_lidar</frame_name>
      </plugin>
    </sensor>
  </gazebo>

  <!-- rear LiDAR controller -->
  <gazebo reference="rear_lidar">
    <sensor type="ray" name="RPLIDAR_s3_rear_sensor">
      <pose>0 0 0 0 0 0</pose>
      <always_on>true</always_on>
      <visualize>true</visualize>
      <update_rate>10</update_rate>
      <ray>
        <scan>
          <horizontal>
            <samples>500</samples>
            <resolution>1</resolution>
            <min_angle>-1.57</min_angle>
            <max_angle>3.1416</max_angle>
            <!-- <max_angle>1.57</max_angle> -->
          </horizontal>
        </scan>
        <range>
          <min>0.10</min>
          <max>30.0</max>
          <resolution>0.01</resolution>
        </range>
        <noise>
          <type>gaussian</type>
          <mean>0.0</mean>
          <stddev>0.01</stddev>
        </noise>
      </ray>
      <plugin name="gazebo_ros_lidar_rear_controller" filename="libgazebo_ros_ray_sensor.so">
        <ros>
            <!-- <namespace>/tb3</namespace> -->
            <remapping>~/out:=/laser/rear</remapping>
          </ros>
        <output_type>sensor_msgs/LaserScan</output_type>
        <frame_name>rear_lidar</frame_name>
      </plugin>
    </sensor>
  </gazebo>

  <gazebo reference="imu_link">
    <sensor name="mecabot_imu" type="imu">
      <always_on>true</always_on>
      <update_rate>50</update_rate>
      <!-- <imu>
        <angular_velocity>
          <x>
            <noise type="gaussian">
              <mean>0.0</mean>
              <stddev>2e-4</stddev>
            </noise>
          </x>
          <y>
            <noise type="gaussian">
              <mean>0.0</mean>
              <stddev>2e-4</stddev>
            </noise>
          </y>
          <z>
            <noise type="gaussian">
              <mean>0.0</mean>
              <stddev>2e-4</stddev>
            </noise>
          </z>
        </angular_velocity>
        <linear_acceleration>
          <x>
            <noise type="gaussian">
              <mean>0.0</mean>
              <stddev>1.7e-2</stddev>
            </noise>
          </x>
          <y>
            <noise type="gaussian">
              <mean>0.0</mean>
              <stddev>1.7e-2</stddev>
            </noise>
          </y>
          <z>
            <noise type="gaussian">
              <mean>0.0</mean>
              <stddev>1.7e-2</stddev>
            </noise>
          </z>
        </linear_acceleration>
      </imu> -->
      <plugin name="mecabot_imu" filename="libgazebo_ros_imu_sensor.so">
        <!-- <frameName>imu_link</frameName> -->
        <frame_name>imu_link</frame_name>
        <!-- <bodyName>imu_link</bodyName> -->
        <ros>
          <!-- <namespace>/tb3</namespace> -->
          <remapping>~/out:=imu</remapping>
          <!-- <frameName>imu_link</frameName> -->
          <!-- <frame_name>imu_link</frame_name> -->
        </ros>
        
        
      </plugin>
    </sensor>
  </gazebo>
</robot>